<?xml version="1.0" ?>
<!-- =================================================================================== -->
<!-- |    This document was autogenerated by xacro from seli.urdf.xacro                | -->
<!-- |    EDITING THIS FILE BY HAND IS NOT RECOMMENDED                                 | -->
<!-- =================================================================================== -->
<robot name="seli">
  <!-- Color -->
  <material name="white">
    <color rgba="1.0 1.0 1.0 1.0"/>
  </material>
  <!-- body Link -->
  <link name="body_link">
    <visual>
      <origin rpy="0 0 0" xyz="0 0 0"/>
      <geometry>
        <mesh filename="package://seli_description/meshes/body.stl" scale="0.001 0.001 0.001"/>
      </geometry>
      <material name="white"/>
    </visual>
    <collision>
      <origin rpy="0 0 0" xyz="0 0 0"/>
      <geometry>
        <mesh filename="package://seli_description/meshes/body.stl" scale="0.001 0.001 0.001"/>
      </geometry>
    </collision>
  </link>
  <!-- Hip link -->
  <link name="lf_hip_link">
    <visual>
      <origin rpy="0 0 0" xyz="0 0 0"/>
      <geometry>
        <mesh filename="package://seli_description/meshes/hip.stl" scale="0.001 0.001 0.001"/>
      </geometry>
      <material name="white"/>
    </visual>
    <collision>
      <origin rpy="0 0 0" xyz="0 0 0"/>
      <geometry>
        <mesh filename="package://seli_description/meshes/hip.stl" scale="0.001 0.001 0.001"/>
      </geometry>
    </collision>
    <inertial>
      <mass value="0.3145"/>
      <inertia ixx="0.0" ixy="0.0" ixz="0.0" iyy="0.0" iyz="0.0" izz="0.0"/>
    </inertial>
  </link>
  <!-- Upper leg link -->
  <link name="lf_upper_leg_link">
    <visual>
      <origin rpy="0 0 0" xyz="0 0 0"/>
      <geometry>
        <mesh filename="package://seli_description/meshes/upper_leg_lf.stl" scale="0.001 0.001 0.001"/>
      </geometry>
      <material name="black"/>
    </visual>
    <collision>
      <origin rpy="0 0 0" xyz="0 0 0"/>
      <geometry>
        <mesh filename="package://seli_description/meshes/upper_leg_lf.stl" scale="0.001 0.001 0.001"/>
      </geometry>
    </collision>
    <inertial>
      <origin xyz="0 0 0"/>
      <mass value="0.3998"/>
      <inertia ixx="0.0" ixy="0.0" ixz="0.0" iyy="0.0" iyz="0.0" izz="0.0"/>
    </inertial>
  </link>
  <!-- Lower leg link -->
  <link name="lf_lower_leg_link">
    <visual>
      <origin rpy="0 0 0" xyz="0 0 0"/>
      <geometry>
        <mesh filename="package://seli_description/meshes/lower_leg.stl" scale="0.001 0.001 0.001"/>
      </geometry>
      <material name="black"/>
    </visual>
    <collision>
      <origin rpy="0 0 0" xyz="0 0 0"/>
      <geometry>
        <mesh filename="package://seli_description/meshes/lower_leg.stl" scale="0.001 0.001 0.001"/>
      </geometry>
    </collision>
    <inertial>
      <origin xyz="0 0 0"/>
      <mass value="0.0423"/>
      <inertia ixx="0.0" ixy="0.0" ixz="0.0" iyy="0.0" iyz="0.0" izz="0.0"/>
    </inertial>
  </link>
  <!-- Foot link -->
  <link name="lf_foot_link"/>
  <!-- Hip joint -->
  <joint name="lf_hip_joint" type="revolute">
    <origin rpy="0 0 0" xyz="0.105 0.088 0"/>
    <parent link="body_link"/>
    <child link="lf_hip_link"/>
    <axis xyz="1 0 0"/>
    <limit effort="0.0" lower="-3.141592653589793" upper="3.141592653589793" velocity="0.0"/>
  </joint>
  <!-- Upper leg joint -->
  <joint name="lf_upper_leg_joint" type="revolute">
    <origin rpy="0 0 0" xyz="0.042 -0.0204 0"/>
    <parent link="lf_hip_link"/>
    <child link="lf_upper_leg_link"/>
    <axis xyz="0 1 0"/>
    <limit effort="0.0" lower="-3.141592653589793" upper="3.141592653589793" velocity="0.0"/>
  </joint>
  <!-- Lower leg joint -->
  <joint name="lf_lower_leg_joint" type="revolute">
    <origin rpy="0 0 0" xyz="-0.1 0.0859 0"/>
    <parent link="lf_upper_leg_link"/>
    <child link="lf_lower_leg_link"/>
    <axis xyz="0 1 0"/>
    <limit effort="0.0" lower="-3.141592653589793" upper="3.141592653589793" velocity="0.0"/>
  </joint>
  <!-- Foot fixed joint -->
  <joint name="lf_foot_joint" type="fixed">
    <origin rpy="0 0 0" xyz="0 0 -0.12656"/>
    <parent link="lf_lower_leg_link"/>
    <child link="lf_foot_link"/>
  </joint>
  <!-- Hip link -->
  <link name="rf_hip_link">
    <visual>
      <origin rpy="3.141592653589793 0 0" xyz="0 0 0"/>
      <geometry>
        <mesh filename="package://seli_description/meshes/hip.stl" scale="0.001 0.001 0.001"/>
      </geometry>
      <material name="white"/>
    </visual>
    <collision>
      <origin rpy="0 0 0" xyz="0 0 0"/>
      <geometry>
        <mesh filename="package://seli_description/meshes/hip.stl" scale="0.001 0.001 0.001"/>
      </geometry>
    </collision>
    <inertial>
      <mass value="0.3145"/>
      <inertia ixx="0.0" ixy="0.0" ixz="0.0" iyy="0.0" iyz="0.0" izz="0.0"/>
    </inertial>
  </link>
  <!-- Upper leg link -->
  <link name="rf_upper_leg_link">
    <visual>
      <origin rpy="0 0 0" xyz="0 0 0"/>
      <geometry>
        <mesh filename="package://seli_description/meshes/upper_leg_rf.stl" scale="0.001 0.001 0.001"/>
      </geometry>
      <material name="black"/>
    </visual>
    <collision>
      <origin rpy="0 0 0" xyz="0 0 0"/>
      <geometry>
        <mesh filename="package://seli_description/meshes/upper_leg_rf.stl" scale="0.001 0.001 0.001"/>
      </geometry>
    </collision>
    <inertial>
      <origin xyz="0 0 0"/>
      <mass value="0.3998"/>
      <inertia ixx="0.0" ixy="0.0" ixz="0.0" iyy="0.0" iyz="0.0" izz="0.0"/>
    </inertial>
  </link>
  <!-- Lower leg link -->
  <link name="rf_lower_leg_link">
    <visual>
      <origin rpy="0 0 0" xyz="0 0 0"/>
      <geometry>
        <mesh filename="package://seli_description/meshes/lower_leg.stl" scale="0.001 0.001 0.001"/>
      </geometry>
      <material name="black"/>
    </visual>
    <collision>
      <origin rpy="0 0 0" xyz="0 0 0"/>
      <geometry>
        <mesh filename="package://seli_description/meshes/lower_leg.stl" scale="0.001 0.001 0.001"/>
      </geometry>
    </collision>
    <inertial>
      <origin xyz="0 0 0"/>
      <mass value="0.0423"/>
      <inertia ixx="0.0" ixy="0.0" ixz="0.0" iyy="0.0" iyz="0.0" izz="0.0"/>
    </inertial>
  </link>
  <!-- Foot link -->
  <link name="rf_foot_link"/>
  <!-- Hip joint -->
  <joint name="rf_hip_joint" type="revolute">
    <origin rpy="0 0 0" xyz="0.105 -0.088 0"/>
    <parent link="body_link"/>
    <child link="rf_hip_link"/>
    <axis xyz="1 0 0"/>
    <limit effort="0.0" lower="-3.141592653589793" upper="3.141592653589793" velocity="0.0"/>
  </joint>
  <!-- Upper leg joint -->
  <joint name="rf_upper_leg_joint" type="revolute">
    <origin rpy="0 0 0" xyz="0.042 0.0204 0"/>
    <parent link="rf_hip_link"/>
    <child link="rf_upper_leg_link"/>
    <axis xyz="0 1 0"/>
    <limit effort="0.0" lower="-3.141592653589793" upper="3.141592653589793" velocity="0.0"/>
  </joint>
  <!-- Lower leg joint -->
  <joint name="rf_lower_leg_joint" type="revolute">
    <origin rpy="0 0 0" xyz="-0.1 -0.0859 0"/>
    <parent link="rf_upper_leg_link"/>
    <child link="rf_lower_leg_link"/>
    <axis xyz="0 1 0"/>
    <limit effort="0.0" lower="-3.141592653589793" upper="3.141592653589793" velocity="0.0"/>
  </joint>
  <!-- Foot fixed joint -->
  <joint name="rf_foot_joint" type="fixed">
    <origin rpy="0 0 0" xyz="0 0 -0.12656"/>
    <parent link="rf_lower_leg_link"/>
    <child link="rf_foot_link"/>
  </joint>
  <!-- Hip link -->
  <link name="lh_hip_link">
    <visual>
      <origin rpy="0 3.141592653589793 0" xyz="0 0 0"/>
      <geometry>
        <mesh filename="package://seli_description/meshes/hip.stl" scale="0.001 0.001 0.001"/>
      </geometry>
      <material name="white"/>
    </visual>
    <collision>
      <origin rpy="0 0 0" xyz="0 0 0"/>
      <geometry>
        <mesh filename="package://seli_description/meshes/hip.stl" scale="0.001 0.001 0.001"/>
      </geometry>
    </collision>
    <inertial>
      <mass value="0.3145"/>
      <inertia ixx="0.0" ixy="0.0" ixz="0.0" iyy="0.0" iyz="0.0" izz="0.0"/>
    </inertial>
  </link>
  <!-- Upper leg link -->
  <link name="lh_upper_leg_link">
    <visual>
      <origin rpy="0 0 0" xyz="0 0 0"/>
      <geometry>
        <mesh filename="package://seli_description/meshes/upper_leg_lh.stl" scale="0.001 0.001 0.001"/>
      </geometry>
      <material name="black"/>
    </visual>
    <collision>
      <origin rpy="0 0 0" xyz="0 0 0"/>
      <geometry>
        <mesh filename="package://seli_description/meshes/upper_leg_lh.stl" scale="0.001 0.001 0.001"/>
      </geometry>
    </collision>
    <inertial>
      <origin xyz="0 0 0"/>
      <mass value="0.3998"/>
      <inertia ixx="0.0" ixy="0.0" ixz="0.0" iyy="0.0" iyz="0.0" izz="0.0"/>
    </inertial>
  </link>
  <!-- Lower leg link -->
  <link name="lh_lower_leg_link">
    <visual>
      <origin rpy="0 0 0" xyz="0 0 0"/>
      <geometry>
        <mesh filename="package://seli_description/meshes/lower_leg.stl" scale="0.001 0.001 0.001"/>
      </geometry>
      <material name="black"/>
    </visual>
    <collision>
      <origin rpy="0 0 0" xyz="0 0 0"/>
      <geometry>
        <mesh filename="package://seli_description/meshes/lower_leg.stl" scale="0.001 0.001 0.001"/>
      </geometry>
    </collision>
    <inertial>
      <origin xyz="0 0 0"/>
      <mass value="0.0423"/>
      <inertia ixx="0.0" ixy="0.0" ixz="0.0" iyy="0.0" iyz="0.0" izz="0.0"/>
    </inertial>
  </link>
  <!-- Foot link -->
  <link name="lh_foot_link"/>
  <!-- Hip joint -->
  <joint name="lh_hip_joint" type="revolute">
    <origin rpy="0 0 0" xyz="-0.105 0.088 0"/>
    <parent link="body_link"/>
    <child link="lh_hip_link"/>
    <axis xyz="1 0 0"/>
    <limit effort="0.0" lower="-3.141592653589793" upper="3.141592653589793" velocity="0.0"/>
  </joint>
  <!-- Upper leg joint -->
  <joint name="lh_upper_leg_joint" type="revolute">
    <origin rpy="0 0 0" xyz="-0.042 -0.0204 0"/>
    <parent link="lh_hip_link"/>
    <child link="lh_upper_leg_link"/>
    <axis xyz="0 1 0"/>
    <limit effort="0.0" lower="-3.141592653589793" upper="3.141592653589793" velocity="0.0"/>
  </joint>
  <!-- Lower leg joint -->
  <joint name="lh_lower_leg_joint" type="revolute">
    <origin rpy="0 0 0" xyz="-0.1 0.0859 0"/>
    <parent link="lh_upper_leg_link"/>
    <child link="lh_lower_leg_link"/>
    <axis xyz="0 1 0"/>
    <limit effort="0.0" lower="-3.141592653589793" upper="3.141592653589793" velocity="0.0"/>
  </joint>
  <!-- Foot fixed joint -->
  <joint name="lh_foot_joint" type="fixed">
    <origin rpy="0 0 0" xyz="0 0 -0.12656"/>
    <parent link="lh_lower_leg_link"/>
    <child link="lh_foot_link"/>
  </joint>
  <!-- Hip link -->
  <link name="rh_hip_link">
    <visual>
      <origin rpy="0 0 3.141592653589793" xyz="0 0 0"/>
      <geometry>
        <mesh filename="package://seli_description/meshes/hip.stl" scale="0.001 0.001 0.001"/>
      </geometry>
      <material name="white"/>
    </visual>
    <collision>
      <origin rpy="0 0 0" xyz="0 0 0"/>
      <geometry>
        <mesh filename="package://seli_description/meshes/hip.stl" scale="0.001 0.001 0.001"/>
      </geometry>
    </collision>
    <inertial>
      <mass value="0.3145"/>
      <inertia ixx="0.0" ixy="0.0" ixz="0.0" iyy="0.0" iyz="0.0" izz="0.0"/>
    </inertial>
  </link>
  <!-- Upper leg link -->
  <link name="rh_upper_leg_link">
    <visual>
      <origin rpy="0 0 0" xyz="0 0 0"/>
      <geometry>
        <mesh filename="package://seli_description/meshes/upper_leg_rh.stl" scale="0.001 0.001 0.001"/>
      </geometry>
      <material name="black"/>
    </visual>
    <collision>
      <origin rpy="0 0 0" xyz="0 0 0"/>
      <geometry>
        <mesh filename="package://seli_description/meshes/upper_leg_rh.stl" scale="0.001 0.001 0.001"/>
      </geometry>
    </collision>
    <inertial>
      <origin xyz="0 0 0"/>
      <mass value="0.3998"/>
      <inertia ixx="0.0" ixy="0.0" ixz="0.0" iyy="0.0" iyz="0.0" izz="0.0"/>
    </inertial>
  </link>
  <!-- Lower leg link -->
  <link name="rh_lower_leg_link">
    <visual>
      <origin rpy="0 0 0" xyz="0 0 0"/>
      <geometry>
        <mesh filename="package://seli_description/meshes/lower_leg.stl" scale="0.001 0.001 0.001"/>
      </geometry>
      <material name="black"/>
    </visual>
    <collision>
      <origin rpy="0 0 0" xyz="0 0 0"/>
      <geometry>
        <mesh filename="package://seli_description/meshes/lower_leg.stl" scale="0.001 0.001 0.001"/>
      </geometry>
    </collision>
    <inertial>
      <origin xyz="0 0 0"/>
      <mass value="0.0423"/>
      <inertia ixx="0.0" ixy="0.0" ixz="0.0" iyy="0.0" iyz="0.0" izz="0.0"/>
    </inertial>
  </link>
  <!-- Foot link -->
  <link name="rh_foot_link"/>
  <!-- Hip joint -->
  <joint name="rh_hip_joint" type="revolute">
    <origin rpy="0 0 0" xyz="-0.105 -0.088 0"/>
    <parent link="body_link"/>
    <child link="rh_hip_link"/>
    <axis xyz="1 0 0"/>
    <limit effort="0.0" lower="-3.141592653589793" upper="3.141592653589793" velocity="0.0"/>
  </joint>
  <!-- Upper leg joint -->
  <joint name="rh_upper_leg_joint" type="revolute">
    <origin rpy="0 0 0" xyz="-0.042 0.0204 0"/>
    <parent link="rh_hip_link"/>
    <child link="rh_upper_leg_link"/>
    <axis xyz="0 1 0"/>
    <limit effort="0.0" lower="-3.141592653589793" upper="3.141592653589793" velocity="0.0"/>
  </joint>
  <!-- Lower leg joint -->
  <joint name="rh_lower_leg_joint" type="revolute">
    <origin rpy="0 0 0" xyz="-0.1 -0.0859 0"/>
    <parent link="rh_upper_leg_link"/>
    <child link="rh_lower_leg_link"/>
    <axis xyz="0 1 0"/>
    <limit effort="0.0" lower="-3.141592653589793" upper="3.141592653589793" velocity="0.0"/>
  </joint>
  <!-- Foot fixed joint -->
  <joint name="rh_foot_joint" type="fixed">
    <origin rpy="0 0 0" xyz="0 0 -0.12656"/>
    <parent link="rh_lower_leg_link"/>
    <child link="rh_foot_link"/>
  </joint>
</robot>
